<?xml version="1.0" ?>
<robot name="turtlebot3_husky">
  <link name="base_footprint"/>
  <link name="base_link">
    <inertial>
      <origin rpy="0 0 0" xyz="0.0 0 0.245"/>
      <inertia ixx="5.5" ixy="0.0" ixz="0.0" iyy="8.0" iyz="0.0" izz="3.5"/>
      <mass value="15.0"/>
    </inertial>
    <visual>
      <origin rpy="0 0 0" xyz="0.0 0 0.245"/>
      <geometry>
        <box size="0.990 0.670 0.390"/>
      </geometry>
      <material>
        <ambient>0.2 0.2 0.2 1</ambient>
        <diffuse>0.5 0.5 0.5 1</diffuse>
        <specular>0.1 0.1 0.1 1</specular>
      </material>
    </visual>
  </link>
  <link name="imu_link"/>
  <link name="base_scan">
    <inertial>
      <origin rpy="0 0 0" xyz="0.195 0 0.830"/>
      <inertia ixx="0.001" ixy="0.000" ixz="0.000" iyy="0.001" iyz="0.000" izz="0.001"/>
      <mass value="0.000001"/>
    </inertial>
    <visual>
      <origin rpy="0 0 0" xyz="0.195 0 0.830"/>
      <geometry>
        <mesh filename="package://turtlebot3_common/meshes/lds.dae" scale="0.001 0.001 0.001"/>
      </geometry>
    </visual>
  </link>
  <link name="camera_link">
    <inertial>
      <origin rpy="0 -0 0" xyz="0 0 0"/>
      <inertia ixx="1" ixy="0" ixz="0" iyy="1" iyz="0" izz="1"/>
      <mass value="0.000001"/>
    </inertial>
    <enable_wind>0</enable_wind>
    <kinematic>0</kinematic>
    <origin rpy="0 -0 0" xyz="0.195 0 0.755"/>
  </link>
  <link name="camera_rgb_frame_1">
    <inertial>
      <origin rpy="0 -0 0" xyz="0.075 0 0"/>
      <inertia ixx="0.001" ixy="0" ixz="0" iyy="0.001" iyz="0" izz="0.001"/>
      <mass value="0.000001"/>
    </inertial>
    <origin rpy="0 -0 0" xyz="0.270 0 0.755"/>
    <enable_wind>0</enable_wind>
    <kinematic>0</kinematic>
  </link>
  <link name="camera_rgb_frame_2">
    <inertial>
      <origin rpy="0 -0 0" xyz="0.0375 0.065 0"/>
      <inertia ixx="0.001" ixy="0" ixz="0" iyy="0.001" iyz="0" izz="0.001"/>
      <mass value="0.000001"/>
    </inertial>
    <origin rpy="0 -0 1.0472" xyz="0.2325 0.065 0.755"/>
    <enable_wind>0</enable_wind>
    <kinematic>0</kinematic>
  </link>
  <link name="camera_rgb_frame_3">
    <inertial>
      <origin rpy="0 -0 0" xyz="-0.0375 0.065 0"/>
      <inertia ixx="0.001" ixy="0" ixz="0" iyy="0.001" iyz="0" izz="0.001"/>
      <mass value="0.000001"/>
    </inertial>
    <origin rpy="0 -0 2.0944" xyz="0.1575 0.065 0.755"/>
    <enable_wind>0</enable_wind>
    <kinematic>0</kinematic>
  </link>
  <link name="camera_rgb_frame_4">
    <inertial>
      <origin rpy="0 -0 0" xyz="-0.075 0 0"/>
      <inertia ixx="0.001" ixy="0" ixz="0" iyy="0.001" iyz="0" izz="0.001"/>
      <mass value="0.000001"/>
    </inertial>
    <origin rpy="0 -0 3.1416" xyz="0.120 0 0.755"/>
    <enable_wind>0</enable_wind>
    <kinematic>0</kinematic>
  </link>
  <link name="camera_rgb_frame_5">
    <inertial>
      <origin rpy="0 -0 0" xyz="-0.0375 -0.065 0"/>
      <inertia ixx="0.001" ixy="0" ixz="0" iyy="0.001" iyz="0" izz="0.001"/>
      <mass value="0.000001"/>
    </inertial>
    <origin rpy="-0 -0 -2.0944" xyz="0.1575 -0.065 0.755"/>
    <enable_wind>0</enable_wind>
    <kinematic>0</kinematic>
  </link>
  <link name="camera_rgb_frame_6">
    <inertial>
      <origin rpy="0 -0 0" xyz="0.0375 -0.065 0"/>
      <inertia ixx="0.001" ixy="0" ixz="0" iyy="0.001" iyz="0" izz="0.001"/>
      <mass value="0.000001"/>
    </inertial>
    <origin rpy="0 0 -1.0472" xyz="0.2325 -0.065 0.755"/>
    <enable_wind>0</enable_wind>
    <kinematic>0</kinematic>
  </link>
  <link name="wheel_left_link">
    <inertial>
      <origin rpy="-1.57 0 0" xyz="0 0.335 0.050"/>
      <inertia ixx="1.8158194e-02" ixy="-9.3392e-11" ixz="1.04909e-10" iyy="3.2922126e-02" iyz="5.75694e-10" izz="1.8158194e-02"/>
      <mass value="2.8498940e-01"/>
    </inertial>
    <visual>
      <origin rpy="0 0 0" xyz="0 0.335 0.050"/>
      <geometry>
        <mesh filename="package://turtlebot3_common/meshes/tire.dae" scale="0.001 0.001 0.001"/>
      </geometry>
    </visual>
  </link>
  <link name="wheel_right_link">
    <inertial>
      <origin rpy="-1.57 0 0" xyz="0.0 -0.335 0.050"/>
      <inertia ixx="1.8158194e-02" ixy="-9.3392e-11" ixz="1.04909e-10" iyy="3.2922126e-02" iyz="5.75694e-10" izz="1.8158194e-02"/>
      <mass value="2.8498940e-01"/>
    </inertial>
    <visual>
      <origin rpy="0 0 0" xyz="0.0 -0.335 0.050"/>
      <geometry>
        <mesh filename="package://turtlebot3_common/meshes/tire.dae" scale="0.001 0.001 0.001"/>
      </geometry>
    </visual>
  </link>
  <link name="caster_back_link">
    <origin rpy="-1.57 0 0" xyz="-0.400 0 0.050"/>
    <inertial>
      <mass value="0.010"/>
      <inertia ixx="0.001" ixy="0.000" ixz="0.000" iyy="0.001" iyz="0.000" izz="0.001"/>
    </inertial>
    <visual>
      <geometry>
        <sphere radius="0.050000"/>
      </geometry>
      <material>
        <ambient>0.1 0.1 0.1 1</ambient>
        <diffuse>0.3 0.3 0.3 1</diffuse>
        <specular>0.1 0.1 0.1 1</specular>
      </material>
    </visual>
  </link>
  <link name="caster_front_link">
    <origin rpy="-1.57 0 0" xyz="0.400 0 0.050"/>
    <inertial>
      <mass value="0.010"/>
      <inertia ixx="0.001" ixy="0.000" ixz="0.000" iyy="0.001" iyz="0.000" izz="0.001"/>
    </inertial>
    <visual>
      <geometry>
        <sphere radius="0.050000"/>
      </geometry>
      <material>
        <ambient>0.1 0.1 0.1 1</ambient>
        <diffuse>0.3 0.3 0.3 1</diffuse>
        <specular>0.1 0.1 0.1 1</specular>
      </material>
    </visual>
  </link>
  <joint name="base_joint" type="fixed">
    <parent link="base_footprint"/>
    <child link="base_link"/>
    <origin rpy="0 0 0" xyz="0.0 0.0 0.050"/>
  </joint>
  <joint name="wheel_left_joint" type="revolute">
    <parent link="base_link"/>
    <child link="wheel_left_link"/>
    <origin rpy="-1.57 0 0" xyz="0.0 0.335 0.050"/>
    <axis xyz="0 0 1"/>
  </joint>
  <joint name="wheel_right_joint" type="revolute">
    <parent link="base_link"/>
    <child link="wheel_right_link"/>
    <origin rpy="-1.57 0 0" xyz="0.0 -0.335 0.050"/>
    <axis xyz="0 0 1"/>
  </joint>
  <joint name="caster_back_joint" type="ball">
    <parent link="base_link"/>
    <child link="caster_back_link"/>
  </joint>
  <joint name="caster_front_joint" type="ball">
    <parent link="base_link"/>
    <child link="caster_front_link"/>
  </joint>
  <joint name="imu_joint" type="fixed">
    <parent link="base_link"/>
    <child link="imu_link"/>
    <origin rpy="0 0 0" xyz="0.0 0 0.245"/>
    <axis xyz="0 0 1"/>
  </joint>
  <joint name="lidar_joint" type="fixed">
    <parent link="base_link"/>
    <child link="base_scan"/>
    <origin rpy="0 0 0" xyz="0.195 0 0.830"/>
    <axis xyz="0 0 1"/>
  </joint>
  <joint name="camera_joint" type="fixed">
    <parent link="base_link"/>
    <child link="camera_link"/>
    <origin rpy="0 -0 0" xyz="0.195 0 0.755"/>
  </joint>
  <joint name="camera_rgb_joint_1" type="fixed">
    <parent link="camera_link"/>
    <child link="camera_rgb_frame_1"/>
    <origin rpy="0 -0 0" xyz="0.075 0 0"/>
  </joint>
  <joint name="camera_rgb_joint_2" type="fixed">
    <parent link="camera_link"/>
    <child link="camera_rgb_frame_2"/>
    <origin rpy="0 -0 1.0472" xyz="0.0375 0.065 0"/>
  </joint>
  <joint name="camera_rgb_joint_3" type="fixed">
    <parent link="camera_link"/>
    <child link="camera_rgb_frame_3"/>
    <origin rpy="0 -0 2.0944" xyz="-0.0375 0.065 0"/>
  </joint>
  <joint name="camera_rgb_joint_4" type="fixed">
    <parent link="camera_link"/>
    <child link="camera_rgb_frame_4"/>
    <origin rpy="0 -0 3.1416" xyz="-0.075 0 0"/>
  </joint>
  <joint name="camera_rgb_joint_5" type="fixed">
    <parent link="camera_link"/>
    <child link="camera_rgb_frame_5"/>
    <origin rpy="0 -0 -2.0944" xyz="-0.0375 -0.065 0"/>
  </joint>
  <joint name="camera_rgb_joint_6" type="fixed">
    <parent link="camera_link"/>
    <child link="camera_rgb_frame_6"/>
    <origin rpy="0 -0 -1.0472" xyz="0.0375 -0.065 0"/>
  </joint>
</robot>
